§quizType
choice

§quizBalls
4

§quizQuestion
What will be logged in console if the call funcs.second() will end with calling reject?



§quizJS
const promise = function (name) {
  const time = Math.round(Math.random() * 3000)

  return new Promise((resolve, reject) => Math.random() < 0.2
    ? reject(`Rejected: ${name}`)
    : setTimeout(() => resolve(`Resolved: ${name}`), time))
}

const funcs = ['first', 'second', 'third']
  .map(name => () => promise(name))

async function getResult () {
  return [
    await funcs[0](),
    await funcs[1](),
    await funcs[2]()
  ]
}

getResult()
  .then(response => console.log(response))
  .catch(err => console.warn(err))



§choiceVariants
Array ['Resolved: first', 'Resolved: second', 'Resolved: third']
Array ['Resolved: first', 'Rejected: second', 'Resolved: third']
Array ['Resolved: first', undefined, 'Resolved: third']
Warning 'Rejected: first'
Warning 'Rejected: second'
Warning 'Rejected: third'


§rightChoice
4
